Workbook

Sheet Sheet1
A1: Ingredients | B1: UOM | C1: Qty. | D1: Kcal | E1: carbs (g) | F1: Protein (g) | G1: fat (g)
A3: Apple | B3: Gms | C3: 25 | D3: 15.5 | E3: 3.27 | F3: 0.07 | G3: 0.16
A4: Pomegranate | B4: Gms | C4: 25 | D4: 13.6 | E4: 2.89 | F4: 0.33 | G4: 0.03
A5: Banana | B5: Gms | C5: 50 | D5: 53.5 | E5: 12.6 | F5: 0.62 | G5: 0.16
A6: Chia Seeds | B6: Gms | C6: 5 | D6: 24.5 | E6: 2.1 | F6: 0.85 | G6: 1.55
A7: Oats | B7: Gms | C7: 50 | D7: 194 | E7: 33 | F7: 8 | G7: 3.5
A8: Mixed fruits Jam | B8: Gms | C8: 25 | D8: 73.03 | E8: 17.6 | F8: 0.48 | G8: 0.07
A9: Mixed Dry Fruits | B9: Gms | C9: 20 | D9: 119.1 | E9: 1.1 | F9: 3.7 | G9: 10.36
A10: Milk | B10: Ml | C10: 200 | D10: 97.8 | E10: 9.8 | F10: 6.52 | G10: 8.8
A12: Milk | B12: ml | C12: 125 | D12: 61.12 | E12: 6.12 | F12: 4.075 | G12: 5.5
A13: coconut Powder | B13: Gms | C13: 10 | D13: 6.82 | E13: 2.39 | F13: 0.71 | G13: 6.2
A14: Chia seeds | B14: Gms | C14: 10 | D14: 49 | E14: 4.2 | F14: 1.7 | G14: 3.1
A15: Mango | B15: Gms | C15: 50 | D15: 20.9 | E15: 4.09 | F15: 0.27 | G15: 0.28
... A26: Banana | B26: nos | C26: 1 | D26: 53.5 | E26: 12.6 | F26: 0.62 | G26: 0.16
A27: Butter | B27: Gms | C27: 5 | D27: 45 | G27: 5
A29: Ragi Malt | B29: Gms | C29: 350 | D29: 240.56 | E29: 50.12 | F29: 5.37 | G29: 1.44
A30: curd | B30: ml | C30: 20 | D30: 11.5 | E30: 0.81 | F30: 0.76 | G30: 0.62
A33: Watermelon | B33: Gms | C33: 150 | D33: 35.8 | E33: 6.24 | F33: 0.6 | G33: 0.24
A35: Papaya | B35: Gms | C35: 150 | D35: 28.16 | E35: 5.81 | F35: 0.9 | G35: 0.21
A38: Watermelon | B38: Gms | C38: 100 | D38: 23.8 | E38: 4.16 | F38: 0.4 | G38: 0.16
A39: Papaya | B39: Gms | C39: 100 | D39: 18.7 | E39: 3.81 | F39: 0.6 | G39: 0.14
A40: Muskmelon | B40: Gms | C40: 30 | D40: 7.18 | E40: 1.28 | F40: 0.13 | G40: 0.14
A41: PineApple | B41: Gms | C41: 30 | D41: 12.9 | E41: 2.78 | F41: 0.15 | G41: 0.12
A42: Kiwi | B42: Gms | C42: 20 | D42: 18 | E42: 4.4 | F42: 0.4 | G42: 0.2
A45: Rice | B45: Gms | C45: 250 | D45: 231.8 | E45: 65.2 | F45: 6.62 | G45: 0.48
A46: Tomato Onion Salad | B46: Gms | C46: 30 | D46: 6.76 | E46: 0.86 | F46: 0.55 | G46: 0.11
A47: Corn,capsium Salad | B47: Gms | C47: 30 | D47: 17.07 | E47: 2.74 | F47: 2.29 | G47: 0.25
... A49: Rajma Masala | B49: Gms | C49: 50 | D49: 74.8 | E49: 12.15 | F49: 4.98 | G49: 0.44
A50: OIL/BUTTER | B50: Gms | C50: 2 | D50: 18 | G50: 2
A52: Rice | B52: Gms | C52: 250 | D52: 231.8 | E52: 65.2 | F52: 6.62 | G52: 0.48
A53: Tomato Onion Salad | B53: Gms | C53: 30 | D53: 6.76 | E53: 0.86 | F53: 0.55 | G53: 0.11
A54: Corn Salad | B54: Gms | C54: 30 | D54: 17.07 | E54: 2.74 | F54: 2.29 | G54: 0.25
A55: Paneer | B55: Gms | C55: 60 | D55: 183.27 | E55: 1.44 | F55: 11.31 | G55: 14.86
A56: Rajma Masala | B56: Gms | C56: 50 | D56: 74.8 | E56: 12.15 | F56: 4.98 | G56: 0.44
A57: OIL/BUTTER | B57: Gms | C57: 2 | D57: 18 | G57: 2
A59: Rice | B59: Gms | C59: 250 | D59: 231.8 | E59: 65.2 | F59: 6.62 | G59: 0.48
A60: Tomato Onion Salad | B60: Gms | C60: 30 | D60: 6.76 | E60: 0.86 | F60: 0.55 | G60: 0.11
A61: Corn Salad | B61: Gms | C61: 30 | D61: 17.07 | E61: 2.74 | F61: 2.29 | G61: 0.25
A62: Soya | B62: Gms | C62: 60 | D62: 81.9 | E62: 7.9 | F62: 12.5 | G62: 0.1
A63: Rajma Masala | B63: Gms | C63: 50 | D63: 74.8 | E63: 12.15 | F63: 4.98 | G63: 0.44
...

Sheet Sheet2
A1: {=UNIQUE(Sheet1!A:A)} -> Ingredients
B2: UOM | C2: Gms | D2: Kcal | E2: Carbs | F2: protien | G2: fats
A3: Apple | B3: =VLOOKUP(A3,Sheet1!A:G,2,false) -> Gms | C3: =VLOOKUP(A3,Sheet1!A:G,3,false) -> 25 | D3: =VLOOKUP(A3,Sheet1!A:G,4,false) -> 15.5 | E3: =VLOOKUP(A3,Sheet1!A:G,5,false) -> 3.27 | F3: =VLOOKUP(A3,Sheet1!A:G,6,false) -> 0.07 | G3: =VLOOKUP(A3,Sheet1!A:G,7,false) -> 0.16
A4: Pomegranate | B4: =VLOOKUP(A4,Sheet1!A:G,2,false) -> Gms | C4: =VLOOKUP(A4,Sheet1!A:G,3,false) -> 25 | D4: =VLOOKUP(A4,Sheet1!A:G,4,false) -> 13.6 | E4: =VLOOKUP(A4,Sheet1!A:G,5,false) -> 2.89 | F4: =VLOOKUP(A4,Sheet1!A:G,6,false) -> 0.33 | G4: =VLOOKUP(A4,Sheet1!A:G,7,false) -> 0.03
A5: Banana | B5: =VLOOKUP(A5,Sheet1!A:G,2,false) -> Gms | C5: =VLOOKUP(A5,Sheet1!A:G,3,false) -> 50 | D5: =VLOOKUP(A5,Sheet1!A:G,4,false) -> 53.5 | E5: =VLOOKUP(A5,Sheet1!A:G,5,false) -> 12.6 | F5: =VLOOKUP(A5,Sheet1!A:G,6,false) -> 0.62 | G5: =VLOOKUP(A5,Sheet1!A:G,7,false) -> 0.16
A6: Chia Seeds | B6: =VLOOKUP(A6,Sheet1!A:G,2,false) -> Gms | C6: =VLOOKUP(A6,Sheet1!A:G,3,false) -> 5 | D6: =VLOOKUP(A6,Sheet1!A:G,4,false) -> 24.5 | E6: =VLOOKUP(A6,Sheet1!A:G,5,false) -> 2.1 | F6: =VLOOKUP(A6,Sheet1!A:G,6,false) -> 0.85 | G6: =VLOOKUP(A6,Sheet1!A:G,7,false) -> 1.55
A7: Oats | B7: =VLOOKUP(A7,Sheet1!A:G,2,false) -> Gms | C7: =VLOOKUP(A7,Sheet1!A:G,3,false) -> 50 | D7: =VLOOKUP(A7,Sheet1!A:G,4,false) -> 194 | E7: =VLOOKUP(A7,Sheet1!A:G,5,false) -> 33 | F7: =VLOOKUP(A7,Sheet1!A:G,6,false) -> 8 | G7: =VLOOKUP(A7,Sheet1!A:G,7,false) -> 3.5
A8: Mixed fruits Jam | B8: =VLOOKUP(A8,Sheet1!A:G,2,false) -> Gms | C8: =VLOOKUP(A8,Sheet1!A:G,3,false) -> 25 | D8: =VLOOKUP(A8,Sheet1!A:G,4,false) -> 73.03 | E8: =VLOOKUP(A8,Sheet1!A:G,5,false) -> 17.6 | F8: =VLOOKUP(A8,Sheet1!A:G,6,false) -> 0.48 | G8: =VLOOKUP(A8,Sheet1!A:G,7,false) -> 0.07
A9: Mixed Dry Fruits | B9: =VLOOKUP(A9,Sheet1!A:G,2,false) -> Gms | C9: =VLOOKUP(A9,Sheet1!A:G,3,false) -> 20 | D9: =VLOOKUP(A9,Sheet1!A:G,4,false) -> 119.1 | E9: =VLOOKUP(A9,Sheet1!A:G,5,false) -> 1.1 | F9: =VLOOKUP(A9,Sheet1!A:G,6,false) -> 3.7 | G9: =VLOOKUP(A9,Sheet1!A:G,7,false) -> 10.36
A10: Milk | B10: =VLOOKUP(A10,Sheet1!A:G,2,false) -> Ml | C10: =VLOOKUP(A10,Sheet1!A:G,3,false) -> 200 | D10: =VLOOKUP(A10,Sheet1!A:G,4,false) -> 97.8 | E10: =VLOOKUP(A10,Sheet1!A:G,5,false) -> 9.8 | F10: =VLOOKUP(A10,Sheet1!A:G,6,false) -> 6.52 | G10: =VLOOKUP(A10,Sheet1!A:G,7,false) -> 8.8
A11: coconut Powder | B11: =VLOOKUP(A11,Sheet1!A:G,2,false) -> Gms | C11: =VLOOKUP(A11,Sheet1!A:G,3,false) -> 10 | D11: =VLOOKUP(A11,Sheet1!A:G,4,false) -> 6.82 | E11: =VLOOKUP(A11,Sheet1!A:G,5,false) -> 2.39 | F11: =VLOOKUP(A11,Sheet1!A:G,6,false) -> 0.71 | G11: =VLOOKUP(A11,Sheet1!A:G,7,false) -> 6.2
A12: Chia seeds | B12: =VLOOKUP(A12,Sheet1!A:G,2,false) -> Gms | C12: =VLOOKUP(A12,Sheet1!A:G,3,false) -> 5 | D12: =VLOOKUP(A12,Sheet1!A:G,4,false) -> 24.5 | E12: =VLOOKUP(A12,Sheet1!A:G,5,false) -> 2.1 | F12: =VLOOKUP(A12,Sheet1!A:G,6,false) -> 0.85 | G12: =VLOOKUP(A12,Sheet1!A:G,7,false) -> 1.55
A13: Mango | B13: =VLOOKUP(A13,Sheet1!A:G,2,false) -> Gms | C13: =VLOOKUP(A13,Sheet1!A:G,3,false) -> 50 | D13: =VLOOKUP(A13,Sheet1!A:G,4,false) -> 20.9 | E13: =VLOOKUP(A13,Sheet1!A:G,5,false) -> 4.09 | F13: =VLOOKUP(A13,Sheet1!A:G,6,false) -> 0.27 | G13: =VLOOKUP(A13,Sheet1!A:G,7,false) -> 0.28
A14: Papaya | B14: =VLOOKUP(A14,Sheet1!A:G,2,false) -> Gms | C14: =VLOOKUP(A14,Sheet1!A:G,3,false) -> 50 | D14: =VLOOKUP(A14,Sheet1!A:G,4,false) -> 9.3 | E14: =VLOOKUP(A14,Sheet1!A:G,5,false) -> 1.9 | F14: =VLOOKUP(A14,Sheet1!A:G,6,false) -> 0.3 | G14: =VLOOKUP(A14,Sheet1!A:G,7,false) -> 0.07
... A44: Stevia | B44: =VLOOKUP(A44,Sheet1!A:G,2,false) -> Gms | C44: =VLOOKUP(A44,Sheet1!A:G,3,false) -> 4 | D44: =VLOOKUP(A44,Sheet1!A:G,4,false) -> 3.2 | E44: =VLOOKUP(A44,Sheet1!A:G,5,false) -> 0.9 | F44: =VLOOKUP(A44,Sheet1!A:G,6,false) -> 0 | G44: =VLOOKUP(A44,Sheet1!A:G,7,false) -> 0
